Workbook

Sheet Assurance Dashboard
B1: API SECURITY TESTING BIBLE
B3: Execution-ready assurance | Candidate → Applicable → Ready → Validate → Remediate → Retest → Close
B5: READINESS RULE • A test is Ready only when applicability, preconditions, identities, data, environment, endpoint/component, safety limits, evidence capture and operational ownership are confirmed. A Passed or Failed result requires observed evidence.
B8: TOTAL TESTS | D8: CRITICAL + HIGH | G8: READY | I8: VALIDATED | L8: OPEN FAILURES
B9: =COUNTA('Security Test Catalogue'!$C$2:$C$484) -> 483 | D9: =COUNTIF('Security Test Catalogue'!$BA$2:$BA$484,"Critical")+COUNTIF('Security Test Catalogue'!$BA$2:$BA$484,"High") -> 267 | G9: =COUNTIF('Security Test Catalogue'!$BD$2:$BD$484,"Ready") -> 0 | I9: =COUNTIF('Security Test Catalogue'!$BD$2:$BD$484,"Passed")+COUNTIF('Security Test Catalogue'!$BD$2:$BD$484,"Failed") -> 0 | L9: =COUNTIF('Security Test Catalogue'!$BD$2:$BD$484,"Failed")+COUNTIF('Security Test Catalogue'!$BD$2:$BD$484,"Remediation in Progress") -> 0
B11: All tests in the bible | D11: Priority risk coverage | G11: All execution prerequisites met | I11: Evidence-backed outcomes | L11: Failure or active remediation
B13: 1 EXECUTION READINESS AND OUTCOMES
B14: Separate planning, readiness, active execution, control outcome and closure. This prevents catalogue completeness being mistaken for assurance.
B16: Lifecycle state | C16: Count | D16: % of catalogue | G16: Ready gate requirement | H16: Required evidence | L16: Result | M16: Minimum decision rule
B17: Candidate | C17: =COUNTIF('Security Test Catalogue'!$BD$2:$BD$484,B17) -> 483 | D17: =IFERROR(C17/$C$29,0) -> 1 | G17: Scope | H17: Authorisation, environment and exact surface | L17: Passed | M17: Expected protection observed with complete evidence.
B18: Applicable | C18: =COUNTIF('Security Test Catalogue'!$BD$2:$BD$484,B18) -> 0 | D18: =IFERROR(C18/$C$29,0) -> 0 | G18: Applicability | H18: Decision and rationale | L18: Failed | M18: Defined failure condition reproduced or control absent.
B19: Ready | C19: =COUNTIF('Security Test Catalogue'!$BD$2:$BD$484,B19) -> 0 | D19: =IFERROR(C19/$C$29,0) -> 0 | G19: Identity | H19: Test and comparison roles available | L19: Blocked | M19: Prerequisite or dependency prevented a valid decision.
B20: In Progress | C20: =COUNTIF('Security Test Catalogue'!$BD$2:$BD$484,B20) -> 0 | D20: =IFERROR(C20/$C$29,0) -> 0 | G20: Data | H20: Synthetic boundary data prepared | L20: Risk Accepted | M20: Approved exception, expiry and compensating control recorded.
B21: Passed | C21: =COUNTIF('Security Test Catalogue'!$BD$2:$BD$484,B21) -> 0 | D21: =IFERROR(C21/$C$29,0) -> 0 | G21: Baseline | H21: Authorised success captured | L21: Closed | M21: Remediation retested or accepted closure evidence exists.
B22: Failed | C22: =COUNTIF('Security Test Catalogue'!$BD$2:$BD$484,B22) -> 0 | D22: =IFERROR(C22/$C$29,0) -> 0 | G22: Safety | H22: Limits, stop and rollback agreed
B23: Blocked | C23: =COUNTIF('Security Test Catalogue'!$BD$2:$BD$484,B23) -> 0 | D23: =IFERROR(C23/$C$29,0) -> 0 | G23: Observability | H23: Evidence and logs available
B24: Remediation in Progress | C24: =COUNTIF('Security Test Catalogue'!$BD$2:$BD$484,B24) -> 0 | D24: =IFERROR(C24/$C$29,0) -> 0 | G24: Ownership | H24: Operational and remediation contacts
B25: Ready for Retest | C25: =COUNTIF('Security Test Catalogue'!$BD$2:$BD$484,B25) -> 0 | D25: =IFERROR(C25/$C$29,0) -> 0
B26: Closed | C26: =COUNTIF('Security Test Catalogue'!$BD$2:$BD$484,B26) -> 0 | D26: =IFERROR(C26/$C$29,0) -> 0
B27: Risk Accepted | C27: =COUNTIF('Security Test Catalogue'!$BD$2:$BD$484,B27) -> 0 | D27: =IFERROR(C27/$C$29,0) -> 0
B28: Not Applicable | C28: =COUNTIF('Security Test Catalogue'!$BD$2:$BD$484,B28) -> 0 | D28: =IFERROR(C28/$C$29,0) -> 0
B29: Total | C29: =SUM(C17:C28) -> 483 | D29: =SUM(D17:D28) -> 1
B31: 2 SECURITY DOMAIN COVERAGE
B32: Completion is based on evidence-backed Passed or Failed outcomes, not on catalogue population.
B34: Security domain | C34: Total | D34: Critical | E34: High | F34: Ready | G34: Validated | H34: Failed | I34: Completion
B35: 1. Identity, Authentication & Session | C35: =COUNTIF('Security Test Catalogue'!$A$2:$A$484,B35) -> 79 | D35: =COUNTIFS('Security Test Catalogue'!$A$2:$A$484,B35,'Security Test Catalogue'!$BA$2:$BA$484,"Critical") -> 2 | E35: =COUNTIFS('Security Test Catalogue'!$A$2:$A$484,B35,'Security Test Catalogue'!$BA$2:$BA$484,"High") -> 74 | F35: =COUNTIFS('Security Test Catalogue'!$A$2:$A$484,B35,'Security Test Catalogue'!$BD$2:$BD$484,"Ready") -> 0 | G35: =COUNTIFS('Security Test Catalogue'!$A$2:$A$484,B35,'Security Test Catalogue'!$BD$2:$BD$484,"Passed")+COUNTIFS('Security Test Catalogue'!$A$2:$A$484,B35,'Security Test Catalogue'!$BD$2:$BD$484,"Failed") -> 0 | H35: =COUNTIFS('Security Test Catalogue'!$A$2:$A$484,B35,'Security Test Catalogue'!$BD$2:$BD$484,"Failed") -> 0 | I35: =IFERROR(G35/C35,0) -> 0
B36: 2. Record & Tenant Access (BOLA / IDOR) | C36: =COUNTIF('Security Test Catalogue'!$A$2:$A$484,B36) -> 22 | D36: =COUNTIFS('Security Test Catalogue'!$A$2:$A$484,B36,'Security Test Catalogue'!$BA$2:$BA$484,"Critical") -> 9 | E36: =COUNTIFS('Security Test Catalogue'!$A$2:$A$484,B36,'Security Test Catalogue'!$BA$2:$BA$484,"High") -> 11 | F36: =COUNTIFS('Security Test Catalogue'!$A$2:$A$484,B36,'Security Test Catalogue'!$BD$2:$BD$484,"Ready") -> 0 | G36: =COUNTIFS('Security Test Catalogue'!$A$2:$A$484,B36,'Security Test Catalogue'!$BD$2:$BD$484,"Passed")+COUNTIFS('Security Test Catalogue'!$A$2:$A$484,B36,'Security Test Catalogue'!$BD$2:$BD$484,"Failed") -> 0 | H36: =COUNTIFS('Security Test Catalogue'!$A$2:$A$484,B36,'Security Test Catalogue'!$BD$2:$BD$484,"Failed") -> 0 | I36: =IFERROR(G36/C36,0) -> 0
B37: 3. Privilege & Function Boundaries (BFLA) | C37: =COUNTIF('Security Test Catalogue'!$A$2:$A$484,B37) -> 35 | D37: =COUNTIFS('Security Test Catalogue'!$A$2:$A$484,B37,'Security Test Catalogue'!$BA$2:$BA$484,"Critical") -> 5 | E37: =COUNTIFS('Security Test Catalogue'!$A$2:$A$484,B37,'Security Test Catalogue'!$BA$2:$BA$484,"High") -> 27 | F37: =COUNTIFS('Security Test Catalogue'!$A$2:$A$484,B37,'Security Test Catalogue'!$BD$2:$BD$484,"Ready") -> 0 | G37: =COUNTIFS('Security Test Catalogue'!$A$2:$A$484,B37,'Security Test Catalogue'!$BD$2:$BD$484,"Passed")+COUNTIFS('Security Test Catalogue'!$A$2:$A$484,B37,'Security Test Catalogue'!$BD$2:$BD$484,"Failed") -> 0 | H37: =COUNTIFS('Security Test Catalogue'!$A$2:$A$484,B37,'Security Test Catalogue'!$BD$2:$BD$484,"Failed") -> 0 | I37: =IFERROR(G37/C37,0) -> 0
B38: 4. Field, Property & Payload Authorisation | C38: =COUNTIF('Security Test Catalogue'!$A$2:$A$484,B38) -> 34 | D38: =COUNTIFS('Security Test Catalogue'!$A$2:$A$484,B38,'Security Test Catalogue'!$BA$2:$BA$484,"Critical") -> 1 | E38: =COUNTIFS('Security Test Catalogue'!$A$2:$A$484,B38,'Security Test Catalogue'!$BA$2:$BA$484,"High") -> 15 | F38: =COUNTIFS('Security Test Catalogue'!$A$2:$A$484,B38,'Security Test Catalogue'!$BD$2:$BD$484,"Ready") -> 0 | G38: =COUNTIFS('Security Test Catalogue'!$A$2:$A$484,B38,'Security Test Catalogue'!$BD$2:$BD$484,"Passed")+COUNTIFS('Security Test Catalogue'!$A$2:$A$484,B38,'Security Test Catalogue'!$BD$2:$BD$484,"Failed") -> 0 | H38: =COUNTIFS('Security Test Catalogue'!$A$2:$A$484,B38,'Security Test Catalogue'!$BD$2:$BD$484,"Failed") -> 0 | I38: =IFERROR(G38/C38,0) -> 0
B39: 5. Input, Parser & Query Safety | C39: =COUNTIF('Security Test Catalogue'!$A$2:$A$484,B39) -> 115 | D39: =COUNTIFS('Security Test Catalogue'!$A$2:$A$484,B39,'Security Test Catalogue'!$BA$2:$BA$484,"Critical") -> 0 | E39: =COUNTIFS('Security Test Catalogue'!$A$2:$A$484,B39,'Security Test Catalogue'!$BA$2:$BA$484,"High") -> 62 | F39: =COUNTIFS('Security Test Catalogue'!$A$2:$A$484,B39,'Security Test Catalogue'!$BD$2:$BD$484,"Ready") -> 0 | G39: =COUNTIFS('Security Test Catalogue'!$A$2:$A$484,B39,'Security Test Catalogue'!$BD$2:$BD$484,"Passed")+COUNTIFS('Security Test Catalogue'!$A$2:$A$484,B39,'Security Test Catalogue'!$BD$2:$BD$484,"Failed") -> 0 | H39: =COUNTIFS('Security Test Catalogue'!$A$2:$A$484,B39,'Security Test Catalogue'!$BD$2:$BD$484,"Failed") -> 0 | I39: =IFERROR(G39/C39,0) -> 0
B40: 6. Data Exposure, Privacy & Cryptography | C40: =COUNTIF('Security Test Catalogue'!$A$2:$A$484,B40) -> 21 | D40: =COUNTIFS('Security Test Catalogue'!$A$2:$A$484,B40,'Security Test Catalogue'!$BA$2:$BA$484,"Critical") -> 0 | E40: =COUNTIFS('Security Test Catalogue'!$A$2:$A$484,B40,'Security Test Catalogue'!$BA$2:$BA$484,"High") -> 18 | F40: =COUNTIFS('Security Test Catalogue'!$A$2:$A$484,B40,'Security Test Catalogue'!$BD$2:$BD$484,"Ready") -> 0 | G40: =COUNTIFS('Security Test Catalogue'!$A$2:$A$484,B40,'Security Test Catalogue'!$BD$2:$BD$484,"Passed")+COUNTIFS('Security Test Catalogue'!$A$2:$A$484,B40,'Security Test Catalogue'!$BD$2:$BD$484,"Failed") -> 0 | H40: =COUNTIFS('Security Test Catalogue'!$A$2:$A$484,B40,'Security Test Catalogue'!$BD$2:$BD$484,"Failed") -> 0 | I40: =IFERROR(G40/C40,0) -> 0
B41: 7. Guest, File & Public Surface Security | C41: =COUNTIF('Security Test Catalogue'!$A$2:$A$484,B41) -> 24 | D41: =COUNTIFS('Security Test Catalogue'!$A$2:$A$484,B41,'Security Test Catalogue'!$BA$2:$BA$484,"Critical") -> 0 | E41: =COUNTIFS('Security Test Catalogue'!$A$2:$A$484,B41,'Security Test Catalogue'!$BA$2:$BA$484,"High") -> 4 | F41: =COUNTIFS('Security Test Catalogue'!$A$2:$A$484,B41,'Security Test Catalogue'!$BD$2:$BD$484,"Ready") -> 0 | G41: =COUNTIFS('Security Test Catalogue'!$A$2:$A$484,B41,'Security Test Catalogue'!$BD$2:$BD$484,"Passed")+COUNTIFS('Security Test Catalogue'!$A$2:$A$484,B41,'Security Test Catalogue'!$BD$2:$BD$484,"Failed") -> 0 | H41: =COUNTIFS('Security Test Catalogue'!$A$2:$A$484,B41,'Security Test Catalogue'!$BD$2:$BD$484,"Failed") -> 0 | I41: =IFERROR(G41/C41,0) -> 0
B42: 8. Integration & Trust Boundary Security | C42: =COUNTIF('Security Test Catalogue'!$A$2:$A$484,B42) -> 47 | D42: =COUNTIFS('Security Test Catalogue'!$A$2:$A$484,B42,'Security Test Catalogue'!$BA$2:$BA$484,"Critical") -> 0 | E42: =COUNTIFS('Security Test Catalogue'!$A$2:$A$484,B42,'Security Test Catalogue'!$BA$2:$BA$484,"High") -> 7 | F42: =COUNTIFS('Security Test Catalogue'!$A$2:$A$484,B42,'Security Test Catalogue'!$BD$2:$BD$484,"Ready") -> 0 | G42: =COUNTIFS('Security Test Catalogue'!$A$2:$A$484,B42,'Security Test Catalogue'!$BD$2:$BD$484,"Passed")+COUNTIFS('Security Test Catalogue'!$A$2:$A$484,B42,'Security Test Catalogue'!$BD$2:$BD$484,"Failed") -> 0 | H42: =COUNTIFS('Security Test Catalogue'!$A$2:$A$484,B42,'Security Test Catalogue'!$BD$2:$BD$484,"Failed") -> 0 | I42: =IFERROR(G42/C42,0) -> 0
B43: 9. Abuse Resistance, Logging & Monitoring | C43: =COUNTIF('Security Test Catalogue'!$A$2:$A$484,B43) -> 15 | D43: =COUNTIFS('Security Test Catalogue'!$A$2:$A$484,B43,'Security Test Catalogue'!$BA$2:$BA$484,"Critical") -> 0 | E43: =COUNTIFS('Security Test Catalogue'!$A$2:$A$484,B43,'Security Test Catalogue'!$BA$2:$BA$484,"High") -> 0 | F43: =COUNTIFS('Security Test Catalogue'!$A$2:$A$484,B43,'Security Test Catalogue'!$BD$2:$BD$484,"Ready") -> 0 | G43: =COUNTIFS('Security Test Catalogue'!$A$2:$A$484,B43,'Security Test Catalogue'!$BD$2:$BD$484,"Passed")+COUNTIFS('Security Test Catalogue'!$A$2:$A$484,B43,'Security Test Catalogue'!$BD$2:$BD$484,"Failed") -> 0 | H43: =COUNTIFS('Security Test Catalogue'!$A$2:$A$484,B43,'Security Test Catalogue'!$BD$2:$BD$484,"Failed") -> 0 | I43: =IFERROR(G43/C43,0) -> 0
B44: 10. Business Logic & Transaction Integrity | C44: =COUNTIF('Security Test Catalogue'!$A$2:$A$484,B44) -> 20 | D44: =COUNTIFS('Security Test Catalogue'!$A$2:$A$484,B44,'Security Test Catalogue'!$BA$2:$BA$484,"Critical") -> 0 | E44: =COUNTIFS('Security Test Catalogue'!$A$2:$A$484,B44,'Security Test Catalogue'!$BA$2:$BA$484,"High") -> 20 | F44: =COUNTIFS('Security Test Catalogue'!$A$2:$A$484,B44,'Security Test Catalogue'!$BD$2:$BD$484,"Ready") -> 0 | G44: =COUNTIFS('Security Test Catalogue'!$A$2:$A$484,B44,'Security Test Catalogue'!$BD$2:$BD$484,"Passed")+COUNTIFS('Security Test Catalogue'!$A$2:$A$484,B44,'Security Test Catalogue'!$BD$2:$BD$484,"Failed") -> 0 | H44: =COUNTIFS('Security Test Catalogue'!$A$2:$A$484,B44,'Security Test Catalogue'!$BD$2:$BD$484,"Failed") -> 0 | I44: =IFERROR(G44/C44,0) -> 0
B45: 11. Configuration, Inventory & Engineering Assurance | C45: =COUNTIF('Security Test Catalogue'!$A$2:$A$484,B45) -> 64 | D45: =COUNTIFS('Security Test Catalogue'!$A$2:$A$484,B45,'Security Test Catalogue'!$BA$2:$BA$484,"Critical") -> 0 | E45: =COUNTIFS('Security Test Catalogue'!$A$2:$A$484,B45,'Security Test Catalogue'!$BA$2:$BA$484,"High") -> 8 | F45: =COUNTIFS('Security Test Catalogue'!$A$2:$A$484,B45,'Security Test Catalogue'!$BD$2:$BD$484,"Ready") -> 0 | G45: =COUNTIFS('Security Test Catalogue'!$A$2:$A$484,B45,'Security Test Catalogue'!$BD$2:$BD$484,"Passed")+COUNTIFS('Security Test Catalogue'!$A$2:$A$484,B45,'Security Test Catalogue'!$BD$2:$BD$484,"Failed") -> 0 | H45: =COUNTIFS('Security Test Catalogue'!$A$2:$A$484,B45,'Security Test Catalogue'!$BD$2:$BD$484,"Failed") -> 0 | I45: =IFERROR(G45/C45,0) -> 0
B46: 12. Client, Platform & General API Assurance | C46: =COUNTIF('Security Test Catalogue'!$A$2:$A$484,B46) -> 7 | D46: =COUNTIFS('Security Test Catalogue'!$A$2:$A$484,B46,'Security Test Catalogue'!$BA$2:$BA$484,"Critical") -> 0 | E46: =COUNTIFS('Security Test Catalogue'!$A$2:$A$484,B46,'Security Test Catalogue'!$BA$2:$BA$484,"High") -> 4 | F46: =COUNTIFS('Security Test Catalogue'!$A$2:$A$484,B46,'Security Test Catalogue'!$BD$2:$BD$484,"Ready") -> 0 | G46: =COUNTIFS('Security Test Catalogue'!$A$2:$A$484,B46,'Security Test Catalogue'!$BD$2:$BD$484,"Passed")+COUNTIFS('Security Test Catalogue'!$A$2:$A$484,B46,'Security Test Catalogue'!$BD$2:$BD$484,"Failed") -> 0 | H46: =COUNTIFS('Security Test Catalogue'!$A$2:$A$484,B46,'Security Test Catalogue'!$BD$2:$BD$484,"Failed") -> 0 | I46: =IFERROR(G46/C46,0) -> 0
B49: 3 MINIMUM EXECUTION EVIDENCE
B50: A test cannot be marked Passed or Failed until the following evidence is present and linked in the catalogue.
B52: Evidence class | C52: Minimum required content
...

Sheet Control Taxonomy
B1: API SECURITY CONTROL TAXONOMY
B3: How the 483 tests are organised: Security Domain → Control Subcategory → Test IDs → Execution dependencies
B5: READING GUIDE • Security Domain is the parent security objective. Control Subcategory identifies the specific control capability being tested. Counts show catalogue concentration and inherent priority. Foundation tests establish baselines; dependent tests reuse identity, data or evidence and must satisfy their dependency gate before execution.
B8: PARENT DOMAINS | D8: CONTROL SUBCATEGORIES | G8: TOTAL TESTS | I8: CRITICAL + HIGH | L8: FOUNDATION TESTS
B9: 12 | D9: 32 | G9: 483 | I9: 267 | L9: 32
B11: Top-level security objectives | D11: Specific control capabilities | G11: Unique catalogue test cases | I11: Priority test coverage | L11: Baseline tests to run first
B13: 1 DOMAIN MAP
B14: Executive view of the 12 parent domains. Use this section to understand purpose, test concentration, priority and foundation coverage.
B16: Security Domain | C16: Security Objective | D16: Primary Review Focus | E16: Tests | F16: Critical | G16: High | H16: Medium | I16: Wave 1 | J16: Blocking Dependencies | K16: Subcategories | L16: Domain Code | M16: Representative Test IDs
B17: 1. Identity, Authentication & Session | C17: Establish trustworthy identity, credential, token and session handling before protected API use. | D17: Authentication strength, token context, MFA, session lifecycle, recovery and service identity. | E17: 79 | F17: 2 | G17: 74 | H17: 3 | I17: 5 | J17: 74 | K17: 5 | L17: IAM | M17: API-IAM-001, API-IAM-002, API-IAM-003, API-IAM-004, API-IAM-005, API-IAM-006 …
B18: 2. Record & Tenant Access (BOLA / IDOR) | C18: Ensure every record-bearing operation enforces object ownership, tenant and entitlement boundaries. | D18: Cross-user IDs, cross-tenant access, nested relationships, search leakage, batch and composite access. | E18: 22 | F18: 9 | G18: 11 | H18: 2 | I18: 1 | J18: 22 | K18: 1 | L18: BOLA | M18: API-BOLA-001, API-BOLA-002, API-BOLA-003, API-BOLA-004, API-BOLA-005, API-BOLA-006 …
B19: 3. Privilege & Function Boundaries (BFLA) | C19: Prevent lower-privilege identities from invoking protected functions or administrative actions. | D19: Role comparison, direct backend invocation, workflow privilege, alternate verbs and hidden routes. | E19: 35 | F19: 5 | G19: 27 | H19: 3 | I19: 3 | J19: 35 | K19: 3 | L19: BFLA | M19: API-BFLA-001, API-BFLA-002, API-BFLA-003, API-BFLA-004, API-BFLA-005, API-BFLA-006 …
B20: 4. Field, Property & Payload Authorisation | C20: Restrict fields and properties that may be read, created, updated, filtered or inferred. | D20: Field access, mass assignment, over-posting, projection, nested properties and inference. | E20: 34 | F20: 1 | G20: 15 | H20: 18 | I20: 2 | J20: 32 | K20: 2 | L20: PROP | M20: API-PROP-001, API-PROP-002, API-PROP-003, API-PROP-004, API-PROP-005, API-PROP-006 …
B21: 5. Input, Parser & Query Safety | C21: Keep untrusted input from changing query scope, parser meaning, execution flow or service stability. | D21: Injection, content types, duplicate parameters, boundaries, deserialisation, encoding and memory safety. | E21: 115 | F21: 0 | G21: 62 | H21: 53 | I21: 2 | J21: 114 | K21: 2 | L21: INPUT | M21: API-INPUT-001, API-INPUT-002, API-INPUT-003, API-INPUT-004, API-INPUT-005, API-INPUT-006 …
B22: 6. Data Exposure, Privacy & Cryptography | C22: Minimise exposed data and protect sensitive information, secrets and cryptographic material. | D22: Response minimisation, secrets, encryption, caching, metadata, pagination and privacy. | E22: 21 | F22: 0 | G22: 18 | H22: 3 | I22: 2 | J22: 20 | K22: 2 | L22: DATA | M22: API-DATA-001, API-DATA-002, API-DATA-003, API-DATA-004, API-DATA-005, API-DATA-006 …
B23: 7. Guest, File & Public Surface Security | C23: Ensure anonymous users and public delivery paths expose only explicitly public content. | D23: Guest APIs, file access, uploads, public links, recovery surfaces, archives and paths. | E23: 24 | F23: 0 | G23: 4 | H23: 20 | I23: 1 | J23: 23 | K23: 1 | L23: PUBLIC | M23: API-PUBLIC-001, API-PUBLIC-002, API-PUBLIC-003, API-PUBLIC-004, API-PUBLIC-005, API-PUBLIC-006 …
B24: 8. Integration & Trust Boundary Security | C24: Constrain trust across middleware, webhooks, service identities and downstream APIs. | D24: SSRF, callbacks, delegated credentials, downstream authorisation, transport integrity and third parties. | E24: 47 | F24: 0 | G24: 7 | H24: 40 | I24: 4 | J24: 47 | K24: 4 | L24: TRUST | M24: API-TRUST-001, API-TRUST-002, API-TRUST-003, API-TRUST-004, API-TRUST-005, API-TRUST-006 …
B25: 9. Abuse Resistance, Logging & Monitoring | C25: Detect and constrain automated abuse, excessive consumption and suspicious access patterns. | D25: Rate limits, quotas, scraping, bulk extraction, logging, correlation, alerting and recovery. | E25: 15 | F25: 0 | G25: 0 | H25: 15 | I25: 2 | J25: 15 | K25: 2 | L25: MON | M25: API-MON-001, API-MON-002, API-MON-003, API-MON-004, API-MON-005, API-MON-006 …
B26: 10. Business Logic & Transaction Integrity | C26: Preserve valid process sequence, state, uniqueness, concurrency and transaction outcomes. | D26: Workflow state, prerequisites, replay, idempotency, race conditions and transaction integrity. | E26: 20 | F26: 0 | G26: 20 | H26: 0 | I26: 4 | J26: 20 | K26: 4 | L26: LOGIC | M26: API-LOGIC-001, API-LOGIC-002, API-LOGIC-003, API-LOGIC-004, API-LOGIC-005, API-LOGIC-006 …
B27: 11. Configuration, Inventory & Engineering Assurance | C27: Maintain secure ownership, configuration, implementation and lifecycle governance for APIs. | D27: Inventory, baselines, code/design, dependencies, deployment, retirement, permissions and training. | E27: 64 | F27: 0 | G27: 8 | H27: 56 | I27: 1 | J27: 64 | K27: 1 | L27: HARD | M27: API-HARD-001, API-HARD-002, API-HARD-003, API-HARD-004, API-HARD-005, API-HARD-006 …
B28: 12. Client, Platform & General API Assurance | C28: Protect browser-facing and platform-level API behaviour outside the core server control domains. | D28: CORS, browser headers, client storage, rendering, protocol contracts and platform exposure. | E28: 7 | F28: 0 | G28: 4 | H28: 3 | I28: 5 | J28: 3 | K28: 5 | L28: PLATFORM | M28: API-PLATFORM-001, API-PLATFORM-002, API-PLATFORM-003, API-PLATFORM-004, API-PLATFORM-005, API-PLATFORM-006 …
B31: 2 DETAILED CONTROL TAXONOMY
B32: Each row is a specific control capability. The description explains what it protects; the metrics show risk concentration, execution style and dependency profile.
A34: Security Domain | B34: Control Subcategory | C34: Control Intent / What It Protects | D34: Tests | E34: Critical | F34: High | G34: Medium | H34: Dynamic | I34: Hybrid | J34: Review | K34: Wave 1 | L34: Blocking | M34: Companion | N34: Representative Test IDs
A35: 1. Identity, Authentication & Session
A36: 1. Identity, Authentication & Session | B36: API Keys & Client Credentials | C36: Validate issuance, scope, storage, rotation, revocation and least privilege for non-user credentials. | D36: 3 | E36: 1 | F36: 2 | G36: 0 | H36: 2 | I36: 1 | J36: 0 | K36: 1 | L36: 2 | M36: 2 | N36: API-IAM-001, API-IAM-003, API-IAM-043
A37: 1. Identity, Authentication & Session | B37: MFA & Step-up Authentication | C37: Verify additional assurance is required and retained for sensitive actions. | D37: 1 | E37: 0 | F37: 1 | G37: 0 | H37: 0 | I37: 1 | J37: 0 | K37: 1 | L37: 0 | M37: 0 | N37: API-IAM-070
A38: 1. Identity, Authentication & Session | B38: Password & Account Recovery | C38: Prevent enumeration, weak reset tokens, recovery bypass and credential abuse. | D38: 2 | E38: 0 | F38: 2 | G38: 0 | H38: 0 | I38: 2 | J38: 0 | K38: 1 | L38: 1 | M38: 2 | N38: API-IAM-027, API-IAM-075
A39: 1. Identity, Authentication & Session | B39: Session Lifecycle & Cookies | C39: Protect session creation, rotation, timeout, logout, replay and browser cookie state. | D39: 21 | E39: 0 | F39: 21 | G39: 0 | H39: 0 | I39: 21 | J39: 0 | K39: 1 | L39: 20 | M39: 2 | N39: API-IAM-007, API-IAM-008, API-IAM-011, API-IAM-012, API-IAM-015, API-IAM-018, API-IAM-023, API-IAM-026, API-IAM-029, API-IAM-034 …
A40: 1. Identity, Authentication & Session | B40: Token Validation & JWT | C40: Validate signature, algorithm, issuer, audience, scope, lifetime, key selection and replay context. | D40: 52 | E40: 1 | F40: 48 | G40: 3 | H40: 20 | I40: 30 | J40: 2 | K40: 1 | L40: 51 | M40: 27 | N40: API-IAM-002, API-IAM-004, API-IAM-005, API-IAM-006, API-IAM-009, API-IAM-010, API-IAM-013, API-IAM-014, API-IAM-016, API-IAM-017 …
A41: Domain total | B41: 1. Identity, Authentication & Session | D41: 79 | E41: 2 | F41: 74 | G41: 3 | H41: 22 | I41: 55 | J41: 2 | K41: 5 | L41: 74 | M41: 33
A43: 2. Record & Tenant Access (BOLA / IDOR)
A44: 2. Record & Tenant Access (BOLA / IDOR) | B44: Object Identifier Authorisation | C44: Ensure knowledge or substitution of an identifier never grants access. | D44: 22 | E44: 9 | F44: 11 | G44: 2 | H44: 12 | I44: 10 | J44: 0 | K44: 1 | L44: 22 | M44: 14 | N44: API-BOLA-001, API-BOLA-002, API-BOLA-003, API-BOLA-004, API-BOLA-005, API-BOLA-006, API-BOLA-007, API-BOLA-008, API-BOLA-009, API-BOLA-010 …
A45: Domain total | B45: 2. Record & Tenant Access (BOLA / IDOR) | D45: 22 | E45: 9 | F45: 11 | G45: 2 | H45: 12 | I45: 10 | J45: 0 | K45: 1 | L45: 22 | M45: 14
A47: 3. Privilege & Function Boundaries (BFLA)
A48: 3. Privilege & Function Boundaries (BFLA) | B48: Administrative Function Access | C48: Restrict configuration and administrative actions to explicitly authorised roles. | D48: 7 | E48: 3 | F48: 3 | G48: 1 | H48: 3 | I48: 3 | J48: 1 | K48: 1 | L48: 7 | M48: 2 | N48: API-BFLA-001, API-BFLA-002, API-BFLA-005, API-BFLA-019, API-BFLA-023, API-BFLA-026, API-BFLA-033
A49: 3. Privilege & Function Boundaries (BFLA) | B49: Function-level Authorisation | C49: Prevent direct invocation of functions hidden or unavailable in the intended client. | D49: 22 | E49: 2 | F49: 19 | G49: 1 | H49: 8 | I49: 14 | J49: 0 | K49: 1 | L49: 22 | M49: 22 | N49: API-BFLA-003, API-BFLA-004, API-BFLA-006, API-BFLA-008, API-BFLA-009, API-BFLA-010, API-BFLA-011, API-BFLA-012, API-BFLA-013, API-BFLA-014 …
A50: 3. Privilege & Function Boundaries (BFLA) | B50: Role & Permission Enforcement | C50: Re-check role, scope and permission on the server for every protected operation. | D50: 6 | E50: 0 | F50: 5 | G50: 1 | H50: 1 | I50: 3 | J50: 2 | K50: 1 | L50: 6 | M50: 6 | N50: API-BFLA-007, API-BFLA-021, API-BFLA-022, API-BFLA-025, API-BFLA-027, API-BFLA-034
A51: Domain total | B51: 3. Privilege & Function Boundaries (BFLA) | D51: 35 | E51: 5 | F51: 27 | G51: 3 | H51: 12 | I51: 20 | J51: 3 | K51: 3 | L51: 35 | M51: 30
A53: 4. Field, Property & Payload Authorisation
...

Sheet Test Dependency Map
A1: Dependent Test ID | B1: Required / Related Test ID | C1: Relationship | D1: Blocking | E1: Invalidates Result if Failed | F1: Reusable Evidence Set ID | G1: Reusable Test Data Set ID | H1: Parallel Execution Group | I1: Recommended Wave | J1: Dependency Gate | K1: Waiver Reference | L1: Rationale
A2: API-IAM-001 | B2: API-BFLA-001 | C2: Companion / corroborating control | D2: No | E2: No | F2: EVD-IAM-API-KEYS-CLIENT-BASE | G2: TDATA-IAM-API-KEYS-CLIENT-BASE | H2: PAR-W1-IAM | I2: Wave 1 - Foundation | J2: Not Required | K2: Not waived | L2: Use configuration baseline as corroborating evidence where available.
A3: API-IAM-002 | B3: API-BFLA-001 | C3: Companion / corroborating control | D3: No | E3: No | F3: EVD-IAM-TOKEN-VALIDATION-BASE | G3: TDATA-IAM-TOKEN-VALIDATION-BASE | H3: PAR-W1-IAM | I3: Wave 1 - Foundation | J3: Not Required | K3: Not waived | L3: Use configuration baseline as corroborating evidence where available.
A4: API-IAM-003 | B4: API-IAM-001 | C4: Blocking prerequisite | D4: Yes | E4: Yes | F4: EVD-IAM-API-KEYS-CLIENT-BASE | G4: TDATA-IAM-API-KEYS-CLIENT-BASE | H4: PAR-W2-IAM | I4: Wave 2 - Control Variants | J4: Not Assessed | K4: Not waived | L4: Establish the baseline control behaviour for 'API Keys & Client Credentials' before testing this variant. Use configuration baseline as corroborating evidence where available.
A5: API-IAM-003 | B5: API-BFLA-001 | C5: Companion / corroborating control | D5: No | E5: No | F5: EVD-IAM-API-KEYS-CLIENT-BASE | G5: TDATA-IAM-API-KEYS-CLIENT-BASE | H5: PAR-W2-IAM | I5: Wave 2 - Control Variants | J5: Not Assessed | K5: Not waived | L5: Establish the baseline control behaviour for 'API Keys & Client Credentials' before testing this variant. Use configuration baseline as corroborating evidence where available.
A6: API-IAM-004 | B6: API-IAM-002 | C6: Blocking prerequisite | D6: Yes | E6: Yes | F6: EVD-IAM-TOKEN-VALIDATION-BASE | G6: TDATA-IAM-TOKEN-VALIDATION-BASE | H6: PAR-W2-IAM | I6: Wave 2 - Control Variants | J6: Not Assessed | K6: Not waived | L6: Establish the baseline control behaviour for 'Token Validation & JWT' before testing this variant. Confirm telemetry and correlation are available before abuse-pattern testing. Use the approved baseline threshold and stop-condition model. Use configuration baseline as corroborating evidence where available.
A7: API-IAM-004 | B7: API-BFLA-015 | C7: Blocking prerequisite | D7: Yes | E7: Yes | F7: EVD-IAM-TOKEN-VALIDATION-BASE | G7: TDATA-IAM-TOKEN-VALIDATION-BASE | H7: PAR-W2-IAM | I7: Wave 2 - Control Variants | J7: Not Assessed | K7: Not waived | L7: Establish the baseline control behaviour for 'Token Validation & JWT' before testing this variant. Confirm telemetry and correlation are available before abuse-pattern testing. Use the approved baseline threshold and stop-condition model. Use configuration baseline as corroborating evidence where available.
A8: API-IAM-004 | B8: API-IAM-016 | C8: Companion / corroborating control | D8: No | E8: No | F8: EVD-IAM-TOKEN-VALIDATION-BASE | G8: TDATA-IAM-TOKEN-VALIDATION-BASE | H8: PAR-W2-IAM | I8: Wave 2 - Control Variants | J8: Not Assessed | K8: Not waived | L8: Establish the baseline control behaviour for 'Token Validation & JWT' before testing this variant. Confirm telemetry and correlation are available before abuse-pattern testing. Use the approved baseline threshold and stop-condition model. Use configuration baseline as corroborating evidence where available.
A9: API-IAM-004 | B9: API-BFLA-001 | C9: Companion / corroborating control | D9: No | E9: No | F9: EVD-IAM-TOKEN-VALIDATION-BASE | G9: TDATA-IAM-TOKEN-VALIDATION-BASE | H9: PAR-W2-IAM | I9: Wave 2 - Control Variants | J9: Not Assessed | K9: Not waived | L9: Establish the baseline control behaviour for 'Token Validation & JWT' before testing this variant. Confirm telemetry and correlation are available before abuse-pattern testing. Use the approved baseline threshold and stop-condition model. Use configuration baseline as corroborating evidence where available.
A10: API-IAM-005 | B10: API-IAM-002 | C10: Blocking prerequisite | D10: Yes | E10: Yes | F10: EVD-IAM-TOKEN-VALIDATION-BASE | G10: TDATA-IAM-TOKEN-VALIDATION-BASE | H10: PAR-W2-IAM | I10: Wave 2 - Control Variants | J10: Not Assessed | K10: Not waived | L10: Establish the baseline control behaviour for 'Token Validation & JWT' before testing this variant. Use configuration baseline as corroborating evidence where available.
A11: API-IAM-005 | B11: API-BFLA-001 | C11: Companion / corroborating control | D11: No | E11: No | F11: EVD-IAM-TOKEN-VALIDATION-BASE | G11: TDATA-IAM-TOKEN-VALIDATION-BASE | H11: PAR-W2-IAM | I11: Wave 2 - Control Variants | J11: Not Assessed | K11: Not waived | L11: Establish the baseline control behaviour for 'Token Validation & JWT' before testing this variant. Use configuration baseline as corroborating evidence where available.
A12: API-IAM-006 | B12: API-IAM-002 | C12: Blocking prerequisite | D12: Yes | E12: Yes | F12: EVD-IAM-TOKEN-VALIDATION-BASE | G12: TDATA-IAM-TOKEN-VALIDATION-BASE | H12: PAR-W2-IAM | I12: Wave 2 - Control Variants | J12: Not Assessed | K12: Not waived | L12: Establish the baseline control behaviour for 'Token Validation & JWT' before testing this variant.
... A1446: API-PLATFORM-007 | B1446: API-PROP-001 | C1446: Companion / corroborating control | D1446: No | E1446: No | F1446: EVD-PLATFORM-CLIENT-SIDE-STOR-BASE | G1446: TDATA-PLATFORM-CLIENT-SIDE-STOR-BASE | H1446: PAR-W2-PLATFORM | I1446: Wave 2 - Control Variants | J1446: Not Assessed | K1446: Not waived | L1446: Establish the baseline control behaviour for 'Client-side Storage & Bootstrap Data' before testing this variant. Establish valid baseline parsing and input constraints. Establish the minimum authorised response and field-visibility baseline.

Sheet Execution Governance
A1: Section | B1: Rule | C1: Minimum evidence / action
A2: State progression | B2: Candidate → Applicable | C2: Applicability Decision and Applicability Rationale completed; scope owner reviewed.
A3: State progression | B3: Applicable → Ready | C3: Preconditions satisfied; target, environment, identities, data, safety, evidence capture and ownership available; Dependency Gate is Ready, Not Required or approved Waived.
A4: State progression | B4: Ready → In Progress | C4: Authorisation active; tester and date recorded; operational contact notified where required.
A5: State progression | B5: In Progress → Passed | C5: Pass criteria met; evidence linked; control observed recorded; no blocking prerequisite failed; limitations documented.
A6: State progression | B6: In Progress → Failed | C6: Failure criteria reproduced; impact and scope recorded; evidence linked; remediation owner and defect process initiated.
A7: State progression | B7: In Progress → Blocked | C7: Baseline, identity, data, target, telemetry, safety approval or prerequisite prevented a valid conclusion. Blocked is never Passed.
A8: Dependency | B8: Blocking prerequisite | C8: Must be Ready or Passed, or satisfied by approved equivalent evidence, before the dependent test is Ready.
A9: Dependency | B9: Non-blocking companion | C9: May remain outstanding; note bounded assurance and execute for corroboration or alternate-path coverage.
A10: Dependency | B10: Evidence/data reuse | C10: Reference the reusable set ID. Do not duplicate or silently modify shared baselines.
A11: Parallel execution | B11: Allowed | C11: No blocking relationship; no shared mutable record/configuration; no single-use credential; no combined traffic distortion; evidence remains independently traceable.
A12: Parallel execution | B12: Not allowed | C12: One test creates another baseline; both modify same state; one revokes identity/configuration; shared quota would distort results.
... A14: Retest | B14: Wave 4 | C14: Retest defect, then regress dependants listed in Invalidated By Failed Test IDs and related companions.

Sheet Security Test Catalogue
A1: Security Domain | B1: Control Subcategory | C1: Test ID | D1: Verification Type | E1: Feature / Surface | F1: Control / Test Scenario | G1: Test Objective | H1: Applicability & Scope | I1: Applicability Decision | J1: Applicability Rationale | K1: Preconditions / Required Test State | L1: Dependency Type | M1: Prerequisite Test IDs | N1: Companion / Related Test IDs | O1: Dependency Rationale | P1: Dependency Gate | Q1: Recommended Execution Wave | R1: Reusable Evidence Set ID | S1: Reusable Test Data Set ID | T1: Invalidated By Failed Test IDs | U1: Parallel Execution Group | V1: Dependency Waiver Reference | W1: Dependency Waiver Rationale | X1: Required Test Identities | Y1: Required Test Data | Z1: Environment | AA1: Ownership Classification | AB1: Logic Controlled By | AC1: Data Exposure Controlled By | AD1: Behaviour Changed By | AE1: User Context | AF1: Role Tested | AG1: Endpoint / Component | AH1: Method / Review Mode | AI1: Attacker Misuse Path | AJ1: Record Access Check | AK1: Privilege Boundary Check | AL1: Input Handling Check | AM1: Data Exposure Check | AN1: Public Access Check | AO1: Safe Validation Procedure | AP1: Safety / Stop Conditions | AQ1: Cleanup / Rollback | AR1: Expected Protected Behaviour | AS1: Pass / Fail Criteria | AT1: Failure Indicates | AU1: Denial / Pass Suggests | AV1: Next Defensive Check | AW1: Business Impact | AX1: OWASP API Security 2023 | AY1: OWASP Top 10 2025 | AZ1: NIST SP 800-53 Rev. 5 | BA1: Severity | BB1: Risk Score | BC1: Execution Priority | BD1: Status | BE1: Execution Date | BF1: Tester | BG1: Actual Result / Finding | BH1: Evidence Required | BI1: Evidence References | BJ1: Control Observed | BK1: Remediation Owner | BL1: Defect ID | BM1: Retest Result | BN1: Notes | BO1: Standards & Guidance URLs
A2: 1. Identity, Authentication & Session | B2: API Keys & Client Credentials | C2: API-IAM-001 | D2: Dynamic | E2: application authentication, external identity provider, OAuth client and token-enabled API surface | F2: API-key scope enforcement | G2: Verify that aPI-key scope enforcement is securely implemented for the scoped surface and cannot be bypassed by an unauthorised, lower-privilege or malformed request context. | H2: Applicable when the API exposes the referenced capability or trust boundary. | I2: Applicable if this authentication mechanism exists | J2: Execute when the scoped surface uses the referenced identity, token, session, credential or recovery capability. | K2: The capability for 'API-key scope enforcement' is confirmed in scope; the exact route, component or configuration object and version are mapped; a successful authorised baseline has been captured; required valid and negative credential/session states are prepared and identity telemetry is accessible; evidence capture and redaction method are ready; authorisation and operational contacts are confirmed. | L2: Non-blocking companions | M2: None identified | N2: API-BFLA-001 | O2: Use configuration baseline as corroborating evidence where available. | P2: Not Required | Q2: Wave 1 - Foundation | R2: EVD-IAM-API-KEYS-CLIENT-BASE | S2: TDATA-IAM-API-KEYS-CLIENT-BASE | T2: None identified | U2: PAR-W1-IAM | V2: Not waived | W2: Not applicable unless Dependency Gate is Waived. If waived, record approver, equivalent evidence, residual uncertainty and expiry/review date. | X2: Valid authenticated user; clean unauthenticated client; controlled invalid, expired, revoked or out-of-context credential variants as applicable. | Y2: Approved test account and controlled credential/token/session variants representing valid, invalid, expired, revoked, replayed and wrong-context states as applicable. | Z2: Authorised test environment representative of production security controls; production testing only where explicitly approved and operationally coordinated. | AA2: Shared responsibility | AB2: platform controls plus The organisation configuration/custom logic | AC2: For 'API-key scope enforcement': The API/data owner defines the minimum authorised response; application authorisation, object/field policy, gateway controls and backing-service permissions enforce exposure. Confirm named accountable teams during scoping. | AD2: For 'API-key scope enforcement': The API product owner approves behaviour; application engineering changes logic; platform/IAM/gateway or data-service owners change policy and enforcement. Confirm named accountable teams during scoping. | AE2: For 'API-key scope enforcement', execute or review as the representative low-privilege authenticated user, a different-role comparison user and an unauthenticated control client where the route is externally reachable. | AF2: Roles for 'API-key scope enforcement': lowest intended consumer role; second role with different entitlement; unauthenticated control where exposed. Replace role classes with actual named roles during assessment setup. | AG2: Target mapping for 'API-key scope enforcement': record the exact login/token/session/recovery/key endpoint, identity-provider/client policy and protected comparison API operation, including environment, version/build, host/base path and owner. Do not mark Ready until mapped. | AH2: Method for 'API-key scope enforcement': capture an authorised baseline; modify only the control-relevant identity, identifier, field, header, parameter, state or trust input; compare status, body, timing, state and logs. Record variants and stop conditions before execution. | AI2: A low-privilege or out-of-context identity attempts to abuse 'api-key scope enforcement' by bypassing the intended control through alternate routes, contexts or malformed inputs to obtain unauthorised data, action, trust or service impact. | AJ2: Not directly applicable to this control. During route discovery, still confirm that any record-bearing request enforces object and tenant boundaries; otherwise cross-reference a dedicated BOLA test. | AK2: Repeat 'api-key scope enforcement' with the lowest authorised role and compare with the approved elevated role; verify server-side function, object, field and workflow-state authorisation. | AL2: For 'api-key scope enforcement', vary identifiers, duplicates, null/blank values, type and length boundaries, unsupported fields, encodings and safe malformed variants relevant to the parser; verify deterministic allowlisting and binding. | AM2: For 'api-key scope enforcement', compare returned or observable data with business need and role visibility; inspect fields, nested objects, metadata, error detail, timing, result limits, logs and cached artefacts for unnecessary disclosure. | AN2: Repeat 'api-key scope enforcement' without a session and using the public or guest context; verify no protected data, action, file, metadata or record-existence signal is available. | AO2: Identify the relevant endpoint and baseline authorized behavior. Execute a controlled negative test for: api-key scope enforcement. Compare authorization, state, response, timing, and audit evidence. | AP2: Use only authorised scope and synthetic or approved test data; stop immediately if protected real data is exposed or unexpected state change occurs; redact secrets and personal data from evidence. | AQ2: Restore the test object, account or session to its recorded baseline; delete synthetic records, tokens, links or files created solely for testing; confirm no queued job, callback or downstream operation remains pending. | AR2: For 'API-key scope enforcement', protected behaviour is: the control operates consistently across intended and negative contexts, fails securely and leaves objective evidence. No unauthorised data, state change, trust expansion or sensitive diagnostic detail is produced. | AS2: PASS when the observed result matches the defined protected behaviour with no data, state, trust or availability weakness. FAIL when the result deviates from the protected behaviour or leaves the control unverifiable. Record the decision against 'api-key scope enforcement'. | AT2: The control for api-key scope enforcement is absent, inconsistently applied or bypassable, indicating a likely authentication and password management weakness across the affected target API and connected-service trust boundary. | AU2: A valid denial or compliant review for 'API-key scope enforcement' suggests identity, credential, token or session validation is effective for the tested context. It does not prove alternate roles, routes, versions, batch paths or trust boundaries; validate the next representative variant. | AV2: Repeat 'API-key scope enforcement' across a second role, alternate API/UI route, related object, batch/composite path and integration context; review telemetry and configuration for systemic coverage. | AW2: If 'API-key scope enforcement' fails, likely impact includes account or service identity compromise and persistent unauthorised access. Primary affected parties: users, service principals and connected services. Current inherent severity is Critical; confirm exposure, data sensitivity, reachability and blast radius before final rating. | AX2: API2:2023 - Broken Authentication | AY2: A07:2025 - Authentication Failures | AZ2: IA | BA2: Critical | BB2: 25 | BC2: P0 - Immediate | BD2: Candidate | BE2: Pending execution | BF2: Unassigned | BG2: Pending execution. Record the observed behaviour, affected data or state, and evidence-based pass/fail rationale. | BH2: Evidence for 'API-key scope enforcement' must include: test ID, date, tester and environment; exact target/component and version; tested identity, role, entitlement and comparison context; expected result, actual result and decision rationale; redacted evidence links and relevant correlation or trace ID; authorised baseline request/response; control-relevant negative request/response; status, headers, body, timing and before/after state. | BI2: Pending execution: link or ID for requests, responses, screenshots, logs, artefacts and correlation records. | BJ2: Pending execution: identify the actual enforcing control or state that no effective control was observed. | BK2: Unassigned: assign only after scope confirmation or finding triage. | BL2: Not raised | BM2: Not Retested | BN2: Execution note for 'API-key scope enforcement': replace all planning placeholders with observed evidence. This test is evidence-backed only for the executed route, role, method, data context and environment. Record untested variants, exclusions and residual risk. | BO2: https://owasp.org/API-Security/editions/2023/en/0x11-t10/ https://owasp.org/Top10/2025/ https://owasp.org/www-project-secure-coding-practices-quick-reference-guide/stable-en/02-checklist/05-checklist.html
A3: 1. Identity, Authentication & Session | B3: Token Validation & JWT | C3: API-IAM-002 | D3: Dynamic | E3: application authentication, external identity provider, OAuth client and token-enabled API surface | F3: Invalid signature rejection | G3: Verify that invalid signature rejection is securely implemented for the scoped surface and cannot be bypassed by an unauthorised, lower-privilege or malformed request context. | H3: Applicable when the API exposes the referenced capability or trust boundary. | I3: Applicable if this authentication mechanism exists | J3: Execute when the scoped surface uses the referenced identity, token, session, credential or recovery capability. | K3: The capability for 'Invalid signature rejection' is confirmed in scope; the exact route, component or configuration object and version are mapped; a successful authorised baseline has been captured; required valid and negative credential/session states are prepared and identity telemetry is accessible; evidence capture and redaction method are ready; authorisation and operational contacts are confirmed. | L3: Non-blocking companions | M3: None identified | N3: API-BFLA-001 | O3: Use configuration baseline as corroborating evidence where available. | P3: Not Required | Q3: Wave 1 - Foundation | R3: EVD-IAM-TOKEN-VALIDATION-BASE | S3: TDATA-IAM-TOKEN-VALIDATION-BASE | T3: None identified | U3: PAR-W1-IAM | V3: Not waived | W3: Not applicable unless Dependency Gate is Waived. If waived, record approver, equivalent evidence, residual uncertainty and expiry/review date. | X3: Valid authenticated user; clean unauthenticated client; controlled invalid, expired, revoked or out-of-context credential variants as applicable. | Y3: Approved test account and controlled credential/token/session variants representing valid, invalid, expired, revoked, replayed and wrong-context states as applicable. | Z3: Authorised test environment representative of production security controls; production testing only where explicitly approved and operationally coordinated. | AA3: Shared responsibility | AB3: platform controls plus The organisation configuration/custom logic | AC3: For 'Invalid signature rejection': The API/data owner defines the minimum authorised response; application authorisation, object/field policy, gateway controls and backing-service permissions enforce exposure. Confirm named accountable teams during scoping. | AD3: For 'Invalid signature rejection': The API product owner approves behaviour; application engineering changes logic; platform/IAM/gateway or data-service owners change policy and enforcement. Confirm named accountable teams during scoping. | AE3: For 'Invalid signature rejection', execute or review as the representative low-privilege authenticated user, a different-role comparison user and an unauthenticated control client where the route is externally reachable. | AF3: Roles for 'Invalid signature rejection': lowest intended consumer role; second role with different entitlement; unauthenticated control where exposed. Replace role classes with actual named roles during assessment setup. | AG3: Target mapping for 'Invalid signature rejection': record the exact login/token/session/recovery/key endpoint, identity-provider/client policy and protected comparison API operation, including environment, version/build, host/base path and owner. Do not mark Ready until mapped. | AH3: Method for 'Invalid signature rejection': capture an authorised baseline; modify only the control-relevant identity, identifier, field, header, parameter, state or trust input; compare status, body, timing, state and logs. Record variants and stop conditions before execution. | AI3: A low-privilege or out-of-context identity attempts to abuse 'invalid signature rejection' by bypassing the intended control through alternate routes, contexts or malformed inputs to obtain unauthorised data, action, trust or service impact. | AJ3: Not directly applicable to this control. During route discovery, still confirm that any record-bearing request enforces object and tenant boundaries; otherwise cross-reference a dedicated BOLA test. | AK3: Repeat 'invalid signature rejection' with the lowest authorised role and compare with the approved elevated role; verify server-side function, object, field and workflow-state authorisation. | AL3: For 'invalid signature rejection', vary identifiers, duplicates, null/blank values, type and length boundaries, unsupported fields, encodings and safe malformed variants relevant to the parser; verify deterministic allowlisting and binding. | AM3: For 'invalid signature rejection', compare returned or observable data with business need and role visibility; inspect fields, nested objects, metadata, error detail, timing, result limits, logs and cached artefacts for unnecessary disclosure. | AN3: Repeat 'invalid signature rejection' without a session and using the public or guest context; verify no protected data, action, file, metadata or record-existence signal is available. | AO3: Identify the relevant endpoint and baseline authorized behavior. Execute a controlled negative test for: invalid signature rejection. Compare authorization, state, response, timing, and audit evidence. | AP3: Use only authorised scope and synthetic or approved test data; stop immediately if protected real data is exposed or unexpected state change occurs; redact secrets and personal data from evidence. | AQ3: Restore the test object, account or session to its recorded baseline; delete synthetic records, tokens, links or files created solely for testing; confirm no queued job, callback or downstream operation remains pending. | AR3: For 'Invalid signature rejection', protected behaviour is: the control operates consistently across intended and negative contexts, fails securely and leaves objective evidence. No unauthorised data, state change, trust expansion or sensitive diagnostic detail is produced. | AS3: PASS when the observed result matches the defined protected behaviour with no data, state, trust or availability weakness. FAIL when the result deviates from the protected behaviour or leaves the control unverifiable. Record the decision against 'invalid signature rejection'. | AT3: The control for invalid signature rejection is absent, inconsistently applied or bypassable, indicating a likely authentication and password management weakness across the affected target API and connected-service trust boundary. | AU3: A valid denial or compliant review for 'Invalid signature rejection' suggests identity, credential, token or session validation is effective for the tested context. It does not prove alternate roles, routes, versions, batch paths or trust boundaries; validate the next representative variant. | AV3: Repeat 'Invalid signature rejection' across a second role, alternate API/UI route, related object, batch/composite path and integration context; review telemetry and configuration for systemic coverage. | AW3: If 'Invalid signature rejection' fails, likely impact includes account or service identity compromise and persistent unauthorised access. Primary affected parties: users, service principals and connected services. Current inherent severity is Critical; confirm exposure, data sensitivity, reachability and blast radius before final rating. | AX3: API2:2023 - Broken Authentication | AY3: A07:2025 - Authentication Failures | AZ3: IA | BA3: Critical | BB3: 25 | BC3: P0 - Immediate | BD3: Candidate | BE3: Pending execution | BF3: Unassigned | BG3: Pending execution. Record the observed behaviour, affected data or state, and evidence-based pass/fail rationale. | BH3: Evidence for 'Invalid signature rejection' must include: test ID, date, tester and environment; exact target/component and version; tested identity, role, entitlement and comparison context; expected result, actual result and decision rationale; redacted evidence links and relevant correlation or trace ID; authorised baseline request/response; control-relevant negative request/response; status, headers, body, timing and before/after state. | BI3: Pending execution: link or ID for requests, responses, screenshots, logs, artefacts and correlation records. | BJ3: Pending execution: identify the actual enforcing control or state that no effective control was observed. | BK3: Unassigned: assign only after scope confirmation or finding triage. | BL3: Not raised | BM3: Not Retested | BN3: Execution note for 'Invalid signature rejection': replace all planning placeholders with observed evidence. This test is evidence-backed only for the executed route, role, method, data context and environment. Record untested variants, exclusions and residual risk. | BO3: https://owasp.org/API-Security/editions/2023/en/0x11-t10/ https://owasp.org/Top10/2025/ https://owasp.org/www-project-secure-coding-practices-quick-reference-guide/stable-en/02-checklist/05-checklist.html
